Workbook

Sheet Overview
A1: BOM Intelligence Overview
A3: Global health check: Dashboard shows scope; Summary queues review; RD records BOM Action in Merge Workspace.
A5: Project | C5: Total PN | E5: Capacitor PN | G5: Estimated Benefit If all accepted, reduce up to 4 redundant PN(s).
A6: P303NV | C6: 907 | E6: 322
A8: Source BOM | C8: 909.0 BOM lines | E8: Unique capacitor PNs
A9: Resistor PN | C9: Capacitor Review | E9: Resistor Review | G9: AI Review Summary Found 22 capacitor group(s) for RD review. Found 18 resistor group(s) for RD review.
A10: 403 | C10: 22 | E10: 18
A12: Unique resistor PNs | C12: similarity groups | E12: similarity groups
A15: ★★★★★ Priority 1
A16: Spec | B16: Merge PN | C16: Merge Qty | D16: Keep PN | E16: Keep Qty | F16: Difference | G16: Difficulty | H16: Action
A17: 100pF 50V NP0 5% 0402 | B17: 11203-0042P000 | C17: 1 | D17: 11203-0042Q000 | E17: 4 | F17: 🟢 Same spec | G17: ★★★★★ Easy | H17: Merge 11203-0042P000 -> 11203-0042Q000
A18: 100nF 16V X7R 10% 0402 | B18: 11G232110411360 | C18: 1 | D18: 11203-0211Q000 | E18: 69 | F18: 🟢 Same spec | G18: ★★★★★ Easy | H18: Merge 11G232110411360 -> 11203-0211Q000
A19: 220nF 25V X7R 10% 0402 | B19: 11203-01763000 | C19: 1 | D19: 11203-0176H000 | E19: 2 | F19: 🟢 Vendor | G19: ★★★★★ Easy | H19: Merge 11203-01763000 -> 11203-0176H000
A44: Generated: 2026-07-24T08:28:28+00:00 | Rules: E:\GitHub\BOM_Normalization_Tool\config\default_rules.json; runtime near-value override | Platform: 2.0.0

Sheet Merge Candidate
A1: Priority | B1: Merge Difficulty | C1: Difference | D1: Spec | E1: Merge PN | F1: Merge Qty | G1: Keep PN | H1: Keep Qty | I1: BOM Qty | J1: Reference Count | K1: Reason | L1: Action | M1: Score
A2: ★★★★★ | B2: ★★★★★ Easy | C2: 🟢 Same spec | D2: 100pF 50V NP0 5% 0402 | E2: 11203-0042P000 | F2: 1 | G2: 11203-0042Q000 | H2: 4 | I2: 5 | J2: 1 | K2: Exact same specification; target PN already has 4 pcs | L2: Merge 11203-0042P000 -> 11203-0042Q000 | M2: 100
A3: ★★★★★ | B3: ★★★★★ Easy | C3: 🟢 Same spec | D3: 100nF 16V X7R 10% 0402 | E3: 11G232110411360 | F3: 1 | G3: 11203-0211Q000 | H3: 69 | I3: 70 | J3: 1 | K3: Exact same specification; target PN already has 69 pcs | L3: Merge 11G232110411360 -> 11203-0211Q000 | M3: 100
A4: ★★★★★ | B4: ★★★★★ Easy | C4: 🟢 Vendor | D4: 220nF 25V X7R 10% 0402 | E4: 11203-01763000 | F4: 1 | G4: 11203-0176H000 | H4: 2 | I4: 3 | J4: 1 | K4: Only vendor is different; target PN already has 2 pcs | L4: Merge 11203-01763000 -> 11203-0176H000 | M4: 98
A5: ★★★★☆ | B5: ★★★★★ Easy | C5: 🟢 Vendor | D5: 100nF 16V X5R 10% 0201 | E5: 11202-0027F000 | F5: 8 | G5: 11202-0027Q000 | H5: 8 | I5: 16 | J5: 8 | K5: Only vendor is different; target PN already has 8 pcs | L5: Merge 11202-0027F000 -> 11202-0027Q000 | M5: 89

Sheet Capacitor Summary
A1: Merge ID | B1: Review Item | C1: BOM Qty | D1: Keep Qty | E1: Merge Qty | F1: Priority | G1: Why Review | H1: BOM Action | I1: Detail
A2: M-001 | B2: 100nF | 16V X7R 10% 0402 | C2: 70 | D2: 69 | E2: 1 | F2: ★★★★★ | G2: Same Spec | H2: =IFERROR(IF(VLOOKUP($A2,'Merge Workspace'!$A:$L,12,FALSE)="","Pending",VLOOKUP($A2,'Merge Workspace'!$A:$L,12,FALSE)),"Pending") | I2: Open
A3: M-002 | B3: 100pF | 50V NP0 5% 0402 | C3: 5 | D3: 4 | E3: 1 | F3: ★★★★★ | G3: Same Spec | H3: =IFERROR(IF(VLOOKUP($A3,'Merge Workspace'!$A:$L,12,FALSE)="","Pending",VLOOKUP($A3,'Merge Workspace'!$A:$L,12,FALSE)),"Pending") | I3: Open
A4: M-003 | B4: 220nF | 25V X7R 10% 0402 | C4: 3 | D4: 2 | E4: 1 | F4: ★★★★★ | G4: Vendor Only | H4: =IFERROR(IF(VLOOKUP($A4,'Merge Workspace'!$A:$L,12,FALSE)="","Pending",VLOOKUP($A4,'Merge Workspace'!$A:$L,12,FALSE)),"Pending") | I4: Open
A5: M-007 | B5: 100nF | 0201⇄0402 | C5: 37 | D5: 25 | E5: 12 | F5: ★★★ | G5: 🟡 Package 0201 ➔ 0402 | H5: =IFERROR(IF(VLOOKUP($A5,'Merge Workspace'!$A:$L,12,FALSE)="","Pending",VLOOKUP($A5,'Merge Workspace'!$A:$L,12,FALSE)),"Pending") | I5: Open
A6: M-008 | B6: 10uF | 0402⇄0603 | C6: 46 | D6: 37 | E6: 9 | F6: ★★★ | G6: 🟡 Package 0402 ➔ 0603 | H6: =IFERROR(IF(VLOOKUP($A6,'Merge Workspace'!$A:$L,12,FALSE)="","Pending",VLOOKUP($A6,'Merge Workspace'!$A:$L,12,FALSE)),"Pending") | I6: Open
A7: M-004 | B7: 100nF | 16V X5R 10% 0201 | C7: 16 | D7: 8 | E7: 8 | F7: ★★★ | G7: Vendor Only | H7: =IFERROR(IF(VLOOKUP($A7,'Merge Workspace'!$A:$L,12,FALSE)="","Pending",VLOOKUP($A7,'Merge Workspace'!$A:$L,12,FALSE)),"Pending") | I7: Open
A8: M-009 | B8: 10uF | 0402⇄0603 | C8: 19 | D8: 12 | E8: 7 | F8: ★★★ | G8: 🟡 Package 0402 ➔ 0603 | H8: =IFERROR(IF(VLOOKUP($A8,'Merge Workspace'!$A:$L,12,FALSE)="","Pending",VLOOKUP($A8,'Merge Workspace'!$A:$L,12,FALSE)),"Pending") | I8: Open
A9: M-005 | B9: 100nF | 0402⇄0603 | C9: 39 | D9: 34 | E9: 5 | F9: ★★★ | G9: 🟡 Package 0603 ➔ 0402 | H9: =IFERROR(IF(VLOOKUP($A9,'Merge Workspace'!$A:$L,12,FALSE)="","Pending",VLOOKUP($A9,'Merge Workspace'!$A:$L,12,FALSE)),"Pending") | I9: Open
A10: M-010 | B10: 2.2uF | 0402⇄0603 | C10: 10 | D10: 5 | E10: 5 | F10: ★★★ | G10: 🟡 Package 0402 ➔ 0603 | H10: =IFERROR(IF(VLOOKUP($A10,'Merge Workspace'!$A:$L,12,FALSE)="","Pending",VLOOKUP($A10,'Merge Workspace'!$A:$L,12,FALSE)),"Pending") | I10: Open
A11: M-011 | B11: 2.2uF | 0201⇄0402 | C11: 9 | D11: 7 | E11: 2 | F11: ★★★ | G11: 🟡 Package 0201 ➔ 0402 | H11: =IFERROR(IF(VLOOKUP($A11,'Merge Workspace'!$A:$L,12,FALSE)="","Pending",VLOOKUP($A11,'Merge Workspace'!$A:$L,12,FALSE)),"Pending") | I11: Open
A12: M-006 | B12: 100nF | 0402⇄0603 | C12: 6 | D12: 4 | E12: 2 | F12: ★★★ | G12: 🟡 Package 0603 ➔ 0402 | H12: =IFERROR(IF(VLOOKUP($A12,'Merge Workspace'!$A:$L,12,FALSE)="","Pending",VLOOKUP($A12,'Merge Workspace'!$A:$L,12,FALSE)),"Pending") | I12: Open
A13: M-012 | B13: 330nF | 0201⇄0402 | C13: 6 | D13: 4 | E13: 2 | F13: ★★★ | G13: 🟡 Package 0402 ➔ 0201 | H13: =IFERROR(IF(VLOOKUP($A13,'Merge Workspace'!$A:$L,12,FALSE)="","Pending",VLOOKUP($A13,'Merge Workspace'!$A:$L,12,FALSE)),"Pending") | I13: Open
... A23: M-020 | B23: 2.2nF | X7R⇄X5R | C23: 2 | D23: 1 | E23: 1 | F23: ★ | G23: 🔴 Material X5R ➔ X7R | H23: =IFERROR(IF(VLOOKUP($A23,'Merge Workspace'!$A:$L,12,FALSE)="","Pending",VLOOKUP($A23,'Merge Workspace'!$A:$L,12,FALSE)),"Pending") | I23: Open

Sheet Merge Workspace
A1: Merge ID | B1: Keep PN | C1: Merge PN | D1: Keep Qty | E1: Merge Qty | F1: Affected RefDes | G1: Estimated Modification | H1: Difference | I1: Package | J1: Voltage | K1: Material | L1: BOM Action
A2: M-001 | B2: 11203-0211Q000 | D2: 69 | H2: KEEP | I2: 0402 | J2: 16V | K2: X7R
A3: M-001 | B3: 11203-0211Q000 | C3: 11G232110411360 | D3: 69 | E3: 1 | F3: C2501 | G3: Update 1 RefDes | H3: Same Spec | I3: 0402 | J3: 16V | K3: X7R
A4: M-002 | B4: 11203-0042Q000 | D4: 4 | H4: KEEP | I4: 0402 | J4: 50V | K4: NP0
A5: M-002 | B5: 11203-0042Q000 | C5: 11203-0042P000 | D5: 4 | E5: 1 | F5: PC2001 | G5: Update 1 RefDes | H5: Same Spec | I5: 0402 | J5: 50V | K5: NP0
A6: M-003 | B6: 11203-0176H000 | D6: 2 | H6: KEEP | I6: 0402 | J6: 25V | K6: X7R
A7: M-003 | B7: 11203-0176H000 | C7: 11203-01763000 | D7: 2 | E7: 1 | F7: C6703 | G7: Update 1 RefDes | H7: Vendor Yageo → Mlcc 0.22Uf | I7: 0402 | J7: 25V | K7: X7R
A8: M-004 | B8: 11202-0027Q000 | D8: 8 | H8: KEEP | I8: 0201 | J8: 16V | K8: X5R
A9: M-004 | B9: 11202-0027Q000 | C9: 11202-0027F000 | D9: 8 | E9: 8 | F9: C3325 C3437 C4601 C4602 C4603 C4604 C7001 C7002 | G9: Update 8 RefDes | H9: Vendor Murata → Mlcc 0.1Uf | I9: 0201 | J9: 16V | K9: X5R
A10: M-005 | B10: 11203-0087Q000 | D10: 34 | H10: KEEP | I10: 0402 | J10: 25V | K10: X7R
A11: M-005 | B11: 11203-0087Q000 | C11: 11G233110412390 | D11: 34 | E11: 5 | F11: PC1239 PC1901 PC1902 PC1906 PC1907 | G11: Update 5 RefDes | H11: Package 0603 → 0402 | I11: 0603 → 0402 | J11: 25V | K11: X7R
A12: M-006 | B12: 11203-0060Q000 | D12: 4 | H12: KEEP | I12: 0402 | J12: 50V | K12: X7R
A13: M-006 | B13: 11203-0060Q000 | C13: 11G233110414390 | D13: 4 | E13: 2 | F13: PC1820 PC2024 | G13: Update 2 RefDes | H13: Package 0603 → 0402 | I13: 0603 → 0402 | J13: 50V | K13: X7R
A14: M-007 | B14: 11G232210415070 | D14: 25 | H14: KEEP | I14: 0402 | J14: 6.3V | K14: X5R
A15: M-007 | B15: 11G232210415070 | C15: 11202-0039Q000 | D15: 25 | E15: 12 | F15: C2402 C2403 C4309 C6202 C6204 C6205 C6206 C7602 C7609 C7615 C7632 C7668 | G15: Update 12 RefDes | H15: Vendor Mlcc 0.1Uf → Walsin Package 0201 → 0402 | I15: 0201 → 0402 | J15: 6.3V | K15: X5R
A16: M-008 | B16: 11G233210625361 | D16: 37 | H16: KEEP | I16: 0603 | J16: 6.3V | K16: X5R
A17: M-008 | B17: 11G233210625361 | C17: 11203-0018Q000 | D17: 37 | E17: 9 | F17: C5601 C5605 C5606 C5633 C5634 C6701 C7004 C7010 C7320 | G17: Update 9 RefDes | H17: Package 0402 → 0603 | I17: 0402 → 0603 | J17: 6.3V | K17: X5R
A18: M-009 | B18: 11204-0024D000 | D18: 12 | H18: KEEP | I18: 0603 | J18: 6.3V | K18: X6S
A19: M-009 | B19: 11204-0024D000 | C19: 11203-0215F000 | D19: 12 | E19: 7 | F19: C3012 C3023 C3031 C3032 C3033 C3034 C3035 | G19: Update 7 RefDes | H19: Vendor Murata → Samsung Package 0402 → 0603 | I19: 0402 → 0603 | J19: 6.3V | K19: X6S
A20: M-010 | B20: 11204-0006Q000 | D20: 5 | H20: KEEP | I20: 0603 | J20: 16V | K20: X5R
A21: M-010 | B21: 11204-0006Q000 | C21: 11203-0030F000 | D21: 5 | E21: 5 | F21: C8112 C8126 PC1510 PC1511 PC1516 | G21: Update 5 RefDes | H21: Vendor Murata → Mlcc 2.2Uf Package 0402 → 0603 | I21: 0402 → 0603 | J21: 16V | K21: X5R
A22: M-011 | B22: 11G232222525320 | D22: 7 | H22: KEEP | I22: 0402 | J22: 6.3V | K22: X5R
A23: M-011 | B23: 11G232222525320 | C23: 11202-0063Q000 | D23: 7 | E23: 2 | F23: C3326 C3438 | G23: Update 2 RefDes | H23: Vendor Mlcc 2.2Uf → Murata Package 0201 → 0402 | I23: 0201 → 0402 | J23: 6.3V | K23: X5R
A24: M-012 | B24: 11202-0447Q000 | D24: 4 | H24: KEEP | I24: 0201 | J24: 6.3V | K24: X5R
A25: M-012 | B25: 11202-0447Q000 | C25: 11203-0182Q100 | D25: 4 | E25: 2 | F25: C7314 C7315 | G25: Update 2 RefDes | H25: Package 0402 → 0201 | I25: 0402 → 0201 | J25: 6.3V | K25: X5R
A26: M-013 | B26: 11203-0322Q000 | D26: 4 | H26: KEEP | I26: 0402 | J26: 25V | K26: X7R
A27: M-013 | B27: 11203-0322Q000 | C27: 11G232110314390 | D27: 4 | E27: 2 | F27: C7201 C7203 | G27: Update 2 RefDes | H27: Voltage 50V → 25V | I27: 0402 | J27: 50V → 25V | K27: X7R
A28: M-014 | B28: 11203-0356Q000 | D28: 11 | H28: KEEP | I28: 0402 | J28: 6.3V | K28: X5R
A29: M-014 | B29: 11203-0356Q000 | C29: 11203-0402F000 | D29: 11 | E29: 4 | F29: C7614 C7626 C7639 C7640 | G29: Update 4 RefDes | H29: Vendor Murata → Mlcc 1Uf Voltage 50V → 6.3V | I29: 0402 | J29: 50V → 6.3V | K29: X5R
A30: M-014 | B30: 11203-0356Q000 | C30: 11203-0003Q000 | D30: 11 | E30: 2 | F30: C4327 C8140 | G30: Update 2 RefDes | H30: Voltage 16V → 6.3V | I30: 0402 | J30: 16V → 6.3V | K30: X5R
A31: M-015 | B31: 11G233210516360 | D31: 3 | H31: KEEP | I31: 0603 | J31: 10V | K31: X5R
A32: M-015 | B32: 11G233210516360 | C32: 11G233210512320 | D32: 3 | E32: 2 | F32: PC1249 PC1824 | G32: Update 2 RefDes | H32: Vendor Murata → Mlcc 1Uf Voltage 25V → 10V | I32: 0603 | J32: 25V → 10V | K32: X5R
A33: M-016 | B33: 11G232222416390 | D33: 6 | H33: KEEP | I33: 0402 | J33: 10V | K33: X5R
A34: M-016 | B34: 11G232222416390 | C34: 11203-0035D000 | D34: 6 | E34: 2 | F34: C8155 PC1205 | G34: Update 2 RefDes | H34: Vendor Samsung → Mlcc 0.22Uf Voltage 6.3V → 10V | I34: 0402 | J34: 6.3V → 10V | K34: X5R
A35: M-017 | B35: 11203-0061F000 | D35: 2 | H35: KEEP | I35: 0402 | J35: 50V | K35: X7R
A36: M-017 | B36: 11203-0061F000 | C36: 11G232122311320 | D36: 2 | E36: 1 | F36: C5707 | G36: Update 1 RefDes | H36: Voltage 16V → 50V | I36: 0402 | J36: 16V → 50V | K36: X7R
A37: M-018 | B37: 11G233247515150 | D37: 11 | H37: KEEP | I37: 0603 | J37: 6.3V | K37: X5R
A38: M-018 | B38: 11G233247515150 | C38: 11204-0010D000 | D38: 11 | E38: 1 | F38: PC0601 | G38: Update 1 RefDes | H38: Voltage 25V → 6.3V | I38: 0603 | J38: 25V → 6.3V | K38: X5R
A39: M-019 | B39: 11G232247415150 | D39: 1 | H39: KEEP | I39: 0402 | J39: 6.3V | K39: X5R
A40: M-019 | B40: 11G232247415150 | C40: 11203-0135D000 | D40: 1 | E40: 1 | F40: C8128 | G40: Update 1 RefDes | H40: Voltage 16V → 6.3V | I40: 0402 | J40: 16V → 6.3V | K40: X5R
...

Sheet Resistor Summary
A1: Value | B1: PN Count | C1: Total Qty | D1: Action / Target PN | E1: BOM Action | F1: Priority | G1: Reason (相似度分类) | H1: Group
A2: 11.8kOhm | B2: 1 | C2: 1 | D2: Review Required | E2: =IFERROR(IF(VLOOKUP($H2,'Resistor Detail'!$A:$K,10,FALSE)="","Pending",VLOOKUP($H2,'Resistor Detail'!$A:$K,10,FALSE)&IF(VLOOKUP($H2,'Resistor Detail'!$A:$K,11,FALSE)="",""," → "&VLOOKUP($H2,'Resistor Detail'!$A:$K,11,FALSE))),"Pending") | F2: ★★ | G2: 🟠 Near Value 11.8kΩ ➔ 12kΩ (-1.66%) Target Value : 12kΩ Package : 0402 Qty : 5 pcs Difference : -1.66% | H2: R001
A3: 2.67kOhm | B3: 1 | C3: 1 | D3: Review Required | E3: =IFERROR(IF(VLOOKUP($H3,'Resistor Detail'!$A:$K,10,FALSE)="","Pending",VLOOKUP($H3,'Resistor Detail'!$A:$K,10,FALSE)&IF(VLOOKUP($H3,'Resistor Detail'!$A:$K,11,FALSE)="",""," → "&VLOOKUP($H3,'Resistor Detail'!$A:$K,11,FALSE))),"Pending") | F3: ★★ | G3: 🟠 Near Value 2.67kΩ ➔ 2.7kΩ (-1.11%) Target Value : 2.7kΩ Package : 0402 Qty : 12 pcs Difference : -1.11% Target Value : 2.74kΩ Package : 0402 Qty : 1 pcs Difference : -2.55% | H3: R002
A4: 2.74kOhm | B4: 1 | C4: 1 | D4: Review Required | E4: =IFERROR(IF(VLOOKUP($H4,'Resistor Detail'!$A:$K,10,FALSE)="","Pending",VLOOKUP($H4,'Resistor Detail'!$A:$K,10,FALSE)&IF(VLOOKUP($H4,'Resistor Detail'!$A:$K,11,FALSE)="",""," → "&VLOOKUP($H4,'Resistor Detail'!$A:$K,11,FALSE))),"Pending") | F4: ★★ | G4: 🟠 Near Value 2.74kΩ ➔ 2.7kΩ (+1.48%) Target Value : 2.7kΩ Package : 0402 Qty : 12 pcs Difference : +1.48% Target Value : 2.67kΩ Package : 0402 Qty : 1 pcs Difference : +2.62% | H4: R003
A5: 20.5kOhm | B5: 1 | C5: 1 | D5: Review Required | E5: =IFERROR(IF(VLOOKUP($H5,'Resistor Detail'!$A:$K,10,FALSE)="","Pending",VLOOKUP($H5,'Resistor Detail'!$A:$K,10,FALSE)&IF(VLOOKUP($H5,'Resistor Detail'!$A:$K,11,FALSE)="",""," → "&VLOOKUP($H5,'Resistor Detail'!$A:$K,11,FALSE))),"Pending") | F5: ★★ | G5: 🟠 Near Value 20.5kΩ ➔ 20kΩ (+2.5%) Target Value : 20kΩ Package : 0402 Qty : 9 pcs Difference : +2.5% | H5: R004
A6: 22.1kOhm | B6: 1 | C6: 1 | D6: Review Required | E6: =IFERROR(IF(VLOOKUP($H6,'Resistor Detail'!$A:$K,10,FALSE)="","Pending",VLOOKUP($H6,'Resistor Detail'!$A:$K,10,FALSE)&IF(VLOOKUP($H6,'Resistor Detail'!$A:$K,11,FALSE)="",""," → "&VLOOKUP($H6,'Resistor Detail'!$A:$K,11,FALSE))),"Pending") | F6: ★★ | G6: 🟠 Near Value 22.1kΩ ➔ 22kΩ (+0.45%) Target Value : 22kΩ Package : 0402 Qty : 2 pcs Difference : +0.45% | H6: R005
A7: 39.2kOhm | B7: 1 | C7: 1 | D7: Review Required | E7: =IFERROR(IF(VLOOKUP($H7,'Resistor Detail'!$A:$K,10,FALSE)="","Pending",VLOOKUP($H7,'Resistor Detail'!$A:$K,10,FALSE)&IF(VLOOKUP($H7,'Resistor Detail'!$A:$K,11,FALSE)="",""," → "&VLOOKUP($H7,'Resistor Detail'!$A:$K,11,FALSE))),"Pending") | F7: ★★ | G7: 🟠 Near Value 39.2kΩ ➔ 40.2kΩ (-2.49%) Target Value : 40.2kΩ Package : 0402 Qty : 2 pcs Difference : -2.49% | H7: R006
A8: 51Ohm | B8: 1 | C8: 1 | D8: Review Required | E8: =IFERROR(IF(VLOOKUP($H8,'Resistor Detail'!$A:$K,10,FALSE)="","Pending",VLOOKUP($H8,'Resistor Detail'!$A:$K,10,FALSE)&IF(VLOOKUP($H8,'Resistor Detail'!$A:$K,11,FALSE)="",""," → "&VLOOKUP($H8,'Resistor Detail'!$A:$K,11,FALSE))),"Pending") | F8: ★★ | G8: 🟠 Near Value 51Ω ➔ 49.9Ω (+2.2%) Target Value : 49.9Ω Package : 0402 Qty : 8 pcs Difference : +2.2% | H8: R007
A9: 10.2kOhm | B9: 1 | C9: 2 | D9: Review Required | E9: =IFERROR(IF(VLOOKUP($H9,'Resistor Detail'!$A:$K,10,FALSE)="","Pending",VLOOKUP($H9,'Resistor Detail'!$A:$K,10,FALSE)&IF(VLOOKUP($H9,'Resistor Detail'!$A:$K,11,FALSE)="",""," → "&VLOOKUP($H9,'Resistor Detail'!$A:$K,11,FALSE))),"Pending") | F9: ★★ | G9: 🟠 Near Value 10.2kΩ ➔ 10kΩ (+2%) Target Value : 10kΩ Package : 0402 Qty : 62 pcs Difference : +2% Target Value : 10.5kΩ Package : 0402 Qty : 2 pcs Difference : -2.86% | H9: R008
A10: 10Ohm | B10: 2 | C10: 4 | D10: Review Required | E10: =IFERROR(IF(VLOOKUP($H10,'Resistor Detail'!$A:$K,10,FALSE)="","Pending",VLOOKUP($H10,'Resistor Detail'!$A:$K,10,FALSE)&IF(VLOOKUP($H10,'Resistor Detail'!$A:$K,11,FALSE)="",""," → "&VLOOKUP($H10,'Resistor Detail'!$A:$K,11,FALSE))),"Pending") | F10: ★★★ | G10: 🟡 Package 0402⇄0603 | H10: R009
A11: 8.2kOhm | B11: 2 | C11: 5 | D11: Review Required | E11: =IFERROR(IF(VLOOKUP($H11,'Resistor Detail'!$A:$K,10,FALSE)="","Pending",VLOOKUP($H11,'Resistor Detail'!$A:$K,10,FALSE)&IF(VLOOKUP($H11,'Resistor Detail'!$A:$K,11,FALSE)="",""," → "&VLOOKUP($H11,'Resistor Detail'!$A:$K,11,FALSE))),"Pending") | F11: ★★★ | G11: 🟡 Package 0603⇄0402 | H11: R010
A12: 1Ohm | B12: 2 | C12: 7 | D12: Review Required | E12: =IFERROR(IF(VLOOKUP($H12,'Resistor Detail'!$A:$K,10,FALSE)="","Pending",VLOOKUP($H12,'Resistor Detail'!$A:$K,10,FALSE)&IF(VLOOKUP($H12,'Resistor Detail'!$A:$K,11,FALSE)="",""," → "&VLOOKUP($H12,'Resistor Detail'!$A:$K,11,FALSE))),"Pending") | F12: ★★★ | G12: 🟡 Package 0402⇄0603 | H12: R011
A13: 4.7Ohm | B13: 2 | C13: 9 | D13: Review Required | E13: =IFERROR(IF(VLOOKUP($H13,'Resistor Detail'!$A:$K,10,FALSE)="","Pending",VLOOKUP($H13,'Resistor Detail'!$A:$K,10,FALSE)&IF(VLOOKUP($H13,'Resistor Detail'!$A:$K,11,FALSE)="",""," → "&VLOOKUP($H13,'Resistor Detail'!$A:$K,11,FALSE))),"Pending") | F13: ★★★ | G13: 🟡 Package 0402⇄0603 | H13: R012
... A19: 0Ohm | B19: 2 | C19: 160 | D19: Review Required | E19: =IFERROR(IF(VLOOKUP($H19,'Resistor Detail'!$A:$K,10,FALSE)="","Pending",VLOOKUP($H19,'Resistor Detail'!$A:$K,10,FALSE)&IF(VLOOKUP($H19,'Resistor Detail'!$A:$K,11,FALSE)="",""," → "&VLOOKUP($H19,'Resistor Detail'!$A:$K,11,FALSE))),"Pending") | F19: ★★★ | G19: 🟡 Package 0402⇄0603 | H19: R018

Sheet Resistor Detail
A1: Group | B1: Row Type | C1: Value | D1: Spec | E1: PN | F1: Qty | G1: Status | H1: Difference | I1: Why Listed | J1: BOM Action | K1: Merge Target
A2: R001 | B2: Value Header | C2: 11.8kOhm | D2: 1 PN | Total 1 pcs | H2: 12kΩ (-1.66%) | I2: 🟠 Near Value 11.8kΩ ➔ 12kΩ (-1.66%) Target Value : 12kΩ Package : 0402 Qty : 5 pcs Difference : -1.66%
A3: R001 | B3: Spec Header | C3: 11.8kOhm | D3: 11.8kOhm 1% 0402 | F3: 1 | G3: Same Spec Group | I3: Qty=1
A4: R001 | B4: PN | C4: 11.8kOhm | D4: 11.8kOhm 1% 0402 | E4: 10G212118214050 | F4: 1 | G4: Target | I4: Qty=1
A5: R001 | B5: Candidate | C5: 12kΩ | D5: 1 PN | Total Qty : 5 pcs Package : 0402 | F5: 5 | G5: Nearby Candidate | H5: '-1.66% | I5: Candidate Value
A6: R001 | B6: Candidate PN | C6: 12kΩ | D6: 12kOhm 1% 0402 | E6: 10G212120214050 | F6: 5 | G6: Nearby Candidate | H6: '-1.66% | I6: Package : 0402
A8: R002 | B8: Value Header | C8: 2.67kOhm | D8: 1 PN | Total 1 pcs | H8: 2.7kΩ (-1.11%), 2.74kΩ (-2.55%) | I8: 🟠 Near Value 2.67kΩ ➔ 2.7kΩ (-1.11%) Target Value : 2.7kΩ Package : 0402 Qty : 12 pcs Difference : -1.11% Target Value : 2.74kΩ Package : 0402 Qty : 1 pcs Difference : -2.55%
A9: R002 | B9: Spec Header | C9: 2.67kOhm | D9: 2.67kOhm 1% 0402 | F9: 1 | G9: Same Spec Group | I9: Qty=1
A10: R002 | B10: PN | C10: 2.67kOhm | D10: 2.67kOhm 1% 0402 | E10: 10G212267114050 | F10: 1 | G10: Target | I10: Qty=1
A11: R002 | B11: Candidate | C11: 2.7kΩ | D11: 1 PN | Total Qty : 12 pcs Package : 0402 | F11: 12 | G11: Nearby Candidate | H11: '-1.11% | I11: Candidate Value
A12: R002 | B12: Candidate PN | C12: 2.7kΩ | D12: 2.7kOhm 1% 0402 | E12: 10G212270114010 | F12: 12 | G12: Nearby Candidate | H12: '-1.11% | I12: Package : 0402
A13: R002 | B13: Candidate | C13: 2.74kΩ | D13: 1 PN | Total Qty : 1 pcs Package : 0402 | F13: 1 | G13: Nearby Candidate | H13: '-2.55% | I13: Candidate Value
A14: R002 | B14: Candidate PN | C14: 2.74kΩ | D14: 2.74kOhm 1% 0402 | E14: 10G212274114010 | F14: 1 | G14: Nearby Candidate | H14: '-2.55% | I14: Package : 0402
A16: R003 | B16: Value Header | C16: 2.74kOhm | D16: 1 PN | Total 1 pcs | H16: 2.7kΩ (+1.48%), 2.67kΩ (+2.62%), 2.87kΩ (-4.53%) | I16: 🟠 Near Value 2.74kΩ ➔ 2.7kΩ (+1.48%) Target Value : 2.7kΩ Package : 0402 Qty : 12 pcs Difference : +1.48% Target Value : 2.67kΩ Package : 0402 Qty : 1 pcs Difference : +2.62%
A17: R003 | B17: Spec Header | C17: 2.74kOhm | D17: 2.74kOhm 1% 0402 | F17: 1 | G17: Same Spec Group | I17: Qty=1
A18: R003 | B18: PN | C18: 2.74kOhm | D18: 2.74kOhm 1% 0402 | E18: 10G212274114010 | F18: 1 | G18: Target | I18: Qty=1
A19: R003 | B19: Candidate | C19: 2.7kΩ | D19: 1 PN | Total Qty : 12 pcs Package : 0402 | F19: 12 | G19: Nearby Candidate | H19: '+1.48% | I19: Candidate Value
A20: R003 | B20: Candidate PN | C20: 2.7kΩ | D20: 2.7kOhm 1% 0402 | E20: 10G212270114010 | F20: 12 | G20: Nearby Candidate | H20: '+1.48% | I20: Package : 0402
A21: R003 | B21: Candidate | C21: 2.67kΩ | D21: 1 PN | Total Qty : 1 pcs Package : 0402 | F21: 1 | G21: Nearby Candidate | H21: '+2.62% | I21: Candidate Value
A22: R003 | B22: Candidate PN | C22: 2.67kΩ | D22: 2.67kOhm 1% 0402 | E22: 10G212267114050 | F22: 1 | G22: Nearby Candidate | H22: '+2.62% | I22: Package : 0402
A23: R003 | B23: Candidate | C23: 2.87kΩ | D23: 1 PN | Total Qty : 1 pcs Package : 0402 | F23: 1 | G23: Nearby Candidate | H23: '-4.53% | I23: Candidate Value
A24: R003 | B24: Candidate PN | C24: 2.87kΩ | D24: 2.87kOhm 1% 0402 | E24: 10G212287114050 | F24: 1 | G24: Nearby Candidate | H24: '-4.53% | I24: Package : 0402
A26: R004 | B26: Value Header | C26: 20.5kOhm | D26: 1 PN | Total 1 pcs | H26: 20kΩ (+2.5%) | I26: 🟠 Near Value 20.5kΩ ➔ 20kΩ (+2.5%) Target Value : 20kΩ Package : 0402 Qty : 9 pcs Difference : +2.5%
A27: R004 | B27: Spec Header | C27: 20.5kOhm | D27: 20.5kOhm 1% 0402 | F27: 1 | G27: Same Spec Group | I27: Qty=1
A28: R004 | B28: PN | C28: 20.5kOhm | D28: 20.5kOhm 1% 0402 | E28: 10G212205214010 | F28: 1 | G28: Target | I28: Qty=1
A29: R004 | B29: Candidate | C29: 20kΩ | D29: 1 PN | Total Qty : 9 pcs Package : 0402 | F29: 9 | G29: Nearby Candidate | H29: '+2.5% | I29: Candidate Value
A30: R004 | B30: Candidate PN | C30: 20kΩ | D30: 20kOhm 1% 0402 | E30: 10G212200214020 | F30: 9 | G30: Nearby Candidate | H30: '+2.5% | I30: Package : 0402
A32: R005 | B32: Value Header | C32: 22.1kOhm | D32: 1 PN | Total 1 pcs | H32: 22kΩ (+0.45%) | I32: 🟠 Near Value 22.1kΩ ➔ 22kΩ (+0.45%) Target Value : 22kΩ Package : 0402 Qty : 2 pcs Difference : +0.45%
A33: R005 | B33: Spec Header | C33: 22.1kOhm | D33: 22.1kOhm 1% 0402 | F33: 1 | G33: Same Spec Group | I33: Qty=1
A34: R005 | B34: PN | C34: 22.1kOhm | D34: 22.1kOhm 1% 0402 | E34: 10G212221214010 | F34: 1 | G34: Target | I34: Qty=1
A35: R005 | B35: Candidate | C35: 22kΩ | D35: 1 PN | Total Qty : 2 pcs Package : 0402 | F35: 2 | G35: Nearby Candidate | H35: '+0.45% | I35: Candidate Value
A36: R005 | B36: Candidate PN | C36: 22kΩ | D36: 22kOhm 1% 0402 | E36: 10G212220214010 | F36: 2 | G36: Nearby Candidate | H36: '+0.45% | I36: Package : 0402
A38: R006 | B38: Value Header | C38: 39.2kOhm | D38: 1 PN | Total 1 pcs | H38: 40.2kΩ (-2.49%), 41.2kΩ (-4.85%) | I38: 🟠 Near Value 39.2kΩ ➔ 40.2kΩ (-2.49%) Target Value : 40.2kΩ Package : 0402 Qty : 2 pcs Difference : -2.49%
A39: R006 | B39: Spec Header | C39: 39.2kOhm | D39: 39.2kOhm 1% 0402 | F39: 1 | G39: Same Spec Group | I39: Qty=1
A40: R006 | B40: PN | C40: 39.2kOhm | D40: 39.2kOhm 1% 0402 | E40: 10G212392214050 | F40: 1 | G40: Target | I40: Qty=1
A41: R006 | B41: Candidate | C41: 40.2kΩ | D41: 1 PN | Total Qty : 2 pcs Package : 0402 | F41: 2 | G41: Nearby Candidate | H41: '-2.49% | I41: Candidate Value
A42: R006 | B42: Candidate PN | C42: 40.2kΩ | D42: 40.2kOhm 1% 0402 | E42: 10G212402214020 | F42: 2 | G42: Nearby Candidate | H42: '-2.49% | I42: Package : 0402
A43: R006 | B43: Candidate | C43: 41.2kΩ | D43: 1 PN | Total Qty : 2 pcs Package : 0402 | F43: 2 | G43: Nearby Candidate | H43: '-4.85% | I43: Candidate Value
A44: R006 | B44: Candidate PN | C44: 41.2kΩ | D44: 41.2kOhm 1% 0402 | E44: 10G212412214010 | F44: 2 | G44: Nearby Candidate | H44: '-4.85% | I44: Package : 0402
A46: R007 | B46: Value Header | C46: 51Ohm | D46: 1 PN | Total 1 pcs | H46: 49.9Ω (+2.2%) | I46: 🟠 Near Value 51Ω ➔ 49.9Ω (+2.2%) Target Value : 49.9Ω Package : 0402 Qty : 8 pcs Difference : +2.2%
...

Sheet Resistor Nearby Value
A1: Current Value | B1: Current BOM Qty | C1: Nearby Value | D1: Candidate Qty | E1: Difference | F1: Tolerance Band | G1: Family | H1: Candidate PNs
A2: 10.2kOhm | B2: 8 | C2: 10kOhm | D2: 248 | E2: '-1.96% | F2: ±2% | G2: 1% 0.0625W 0402 | H2: 10G212100214020, 10G212100214010, 10G212100214030, 10G212100214050
A3: 10.2kOhm | B3: 8 | C3: 10.5kOhm | D3: 8 | E3: '+2.94% | F3: ±5% | G3: 1% 0.0625W 0402 | H3: 10G212105214050, 10G212105214020, 10G212105214010, 10G212105214030
A4: 10.5kOhm | B4: 8 | C4: 10.2kOhm | D4: 8 | E4: '-2.86% | F4: ±5% | G4: 1% 0.0625W 0402 | H4: 10G212102214020, 10G212102214050, 10G212102214010, 10G212102214031
A5: 10.5kOhm | B5: 8 | C5: 10kOhm | D5: 248 | E5: '-4.76% | F5: ±5% | G5: 1% 0.0625W 0402 | H5: 10G212100214020, 10G212100214010, 10G212100214030, 10G212100214050
A6: 100kOhm | B6: 264 | C6: 90.9kOhm | D6: 4 | E6: '-9.1% | F6: ±10% | G6: 1% 0.0625W 0402 | H6: 10G212909214050, 10G212909214010, 10G212909214020, 10G212909214030
A7: 10kOhm | B7: 248 | C7: 10.2kOhm | D7: 8 | E7: '+2% | F7: ±2% | G7: 1% 0.0625W 0402 | H7: 10G212102214020, 10G212102214050, 10G212102214010, 10G212102214031
A8: 10kOhm | B8: 248 | C8: 10.5kOhm | D8: 8 | E8: '+5% | F8: ±5% | G8: 1% 0.0625W 0402 | H8: 10G212105214050, 10G212105214020, 10G212105214010, 10G212105214030
A9: 11.8kOhm | B9: 4 | C9: 12kOhm | D9: 20 | E9: '+1.69% | F9: ±2% | G9: 1% 0.0625W 0402 | H9: 10G212120214050, 10G212120214010, 10G212120214020, 10G212120214030
A10: 12kOhm | B10: 20 | C10: 11.8kOhm | D10: 4 | E10: '-1.66% | F10: ±2% | G10: 1% 0.0625W 0402 | H10: 10G212118214050, 10G212118214010, 10G212118214030, 10G212118214020
A11: 16.2kOhm | B11: 4 | C11: 16.9kOhm | D11: 4 | E11: '+4.32% | F11: ±5% | G11: 1% 0.0625W 0402 | H11: 10G212169214050, 10G212169214010, 10G212169214020, 10G212169214030
A12: 16.9kOhm | B12: 4 | C12: 16.2kOhm | D12: 4 | E12: '-4.14% | F12: ±5% | G12: 1% 0.0625W 0402 | H12: 10G212162214010, 10G212162214020, 10G212162214030, 10G212162214050
A13: 18.7kOhm | B13: 8 | C13: 20kOhm | D13: 45 | E13: '+6.95% | F13: ±10% | G13: 1% 0.0625W 0402 | H13: 10G212200214020, 10G212200214010, 10G212200214030, 10G212200214050, 10102-00811100
... A104: 8.66kOhm | B104: 4 | C104: 8.2kOhm | D104: 16 | E104: '-5.31% | F104: ±10% | G104: 1% 0.0625W 0402 | H104: 10G212820114050, 10G212820114010, 10G212820114020, 10G212820114030

Sheet AVL Candidate
A1: Spec | B1: Preferred PN | C1: PN Count | D1: Vendor | E1: Qty | F1: Status | G1: Suggestion
A2: C_0.5pF_50V_NP0___0402 | B2: 11203-0282Q000 | C2: 4 | D2: Mlcc 0.5Pf, Samsung, Walsin | E2: 4 | F2: Ready for unified AVL | G2: Review the suggested preferred PN and publish one controlled AVL entry.
A3: C_1.8pF_50V_NP0___0402 | B3: 11203-0091F100 | C3: 1 | D3: Murata | E3: 2 | F3: Single-source gap | G3: Source and qualify at least one alternate manufacturer.
A4: C_100nF_16V_X5R__10%_0201 | B4: 11202-0027D000 | C4: 4 | D4: Murata, Mlcc 0.1Uf, Samsung | E4: 32 | F4: Ready for unified AVL | G4: Review the suggested preferred PN and publish one controlled AVL entry.
A5: C_100nF_16V_X5R__10%_0402 | B5: 11203-0232Q000 | C5: 5 | D5: Samsung, Murata, Mlcc 0.1Uf, Yageo | E5: 25 | F5: Ready for unified AVL | G5: Review the suggested preferred PN and publish one controlled AVL entry.
A6: C_100nF_16V_X7R__10%_0402 | B6: 11203-0211P000 | C6: 7 | D6: Mlcc 0.1Uf, Yageo, Samsung, Walsin, Murata | E6: 415 | F6: Ready for unified AVL | G6: Review the suggested preferred PN and publish one controlled AVL entry.
A7: C_100nF_16V_X7R__5%_0603 | B7: 11G233110401070 | C7: 3 | D7: Walsin, TDK, Murata | E7: 24 | F7: Ready for unified AVL | G7: Review the suggested preferred PN and publish one controlled AVL entry.
A8: C_100nF_25V_X7R__10%_0402 | B8: 11203-00873000 | C8: 5 | D8: Mlcc 0.1Uf, Samsung, Murata, Yageo, Walsin | E8: 170 | F8: Ready for unified AVL | G8: Review the suggested preferred PN and publish one controlled AVL entry.
A9: C_100nF_25V_X7R__10%_0603 | B9: 11204-0125Q100 | C9: 5 | D9: Mlcc 0.1Uf, Yageo, Samsung, Murata | E9: 25 | F9: Ready for unified AVL | G9: Review the suggested preferred PN and publish one controlled AVL entry.
A10: C_100nF_50V_X7R__10%_0402 | B10: 11203-0060Q000 | C10: 1 | D10: Mlcc 0.1Uf | E10: 4 | F10: Single-source gap | G10: Source and qualify at least one alternate manufacturer.
A11: C_100nF_50V_X7R__10%_0603 | B11: 11204-0069Q000 | C11: 5 | D11: Mlcc 0.1Uf, Yageo, Samsung, Murata | E11: 10 | F11: Ready for unified AVL | G11: Review the suggested preferred PN and publish one controlled AVL entry.
A12: C_100nF_6.3V_X5R__10%_0201 | B12: 11202-0039Q000 | C12: 5 | D12: Mlcc 0.1Uf, Yageo, Murata, Samsung | E12: 60 | F12: Ready for unified AVL | G12: Review the suggested preferred PN and publish one controlled AVL entry.
A13: C_100nF_6.3V_X5R__10%_0402 | B13: 11203-0014F000 | C13: 2 | D13: Walsin, Murata | E13: 50 | F13: Ready for unified AVL | G13: Review the suggested preferred PN and publish one controlled AVL entry.
... A100: R_1kOhm_5%_0.25W__1206 | B100: 10G216102001010 | C100: 3 | D100: Yageo, Res 1K Ohm 1 | E100: 3 | F100: Ready for unified AVL | G100: Review the suggested preferred PN and publish one controlled AVL entry.
A101: R_1mOhm_1%_3W__2512 | B101: 10108-00241000 | C101: 2 | E101: 2 | F101: Single-source gap | G101: Source and qualify at least one alternate manufacturer.
A102: R_2.2Ohm_1%_0.0625W__0402 | B102: 10G2122R2014010 | C102: 4 | D102: Yageo, Res 2.2 Ohm 1 | E102: 40 | F102: Ready for unified AVL | G102: Review the suggested preferred PN and publish one controlled AVL entry.
A103: R_2.2Ohm_5%_0.1W__0603 | B103: 10G2132R2003010 | C103: 4 | D103: Res 2.2 Ohm 1, Yageo | E103: 36 | F103: Ready for unified AVL | G103: Review the suggested preferred PN and publish one controlled AVL entry.
A104: R_2.2kOhm_1%_0.0625W__0402 | B104: 10G212220114010 | C104: 4 | D104: Res 2.2K Ohm 1, Yageo | E104: 88 | F104: Ready for unified AVL | G104: Review the suggested preferred PN and publish one controlled AVL entry.
A105: R_2.67kOhm_1%_0.0625W__0402 | B105: 10G212267114010 | C105: 4 | D105: Res 2.67K Ohm 1, Yageo | E105: 4 | F105: Ready for unified AVL | G105: Review the suggested preferred PN and publish one controlled AVL entry.
A106: R_2.74kOhm_1%_0.0625W__0402 | B106: 10G212274114010 | C106: 4 | D106: Res 2.74K Ohm 1, Yageo | E106: 4 | F106: Ready for unified AVL | G106: Review the suggested preferred PN and publish one controlled AVL entry.
A107: R_2.7kOhm_1%_0.0625W__0402 | B107: 10G212270114010 | C107: 4 | D107: Res 2.7K Ohm 1, Yageo | E107: 48 | F107: Ready for unified AVL | G107: Review the suggested preferred PN and publish one controlled AVL entry.
A108: R_2.87kOhm_1%_0.0625W__0402 | B108: 10G212287114010 | C108: 4 | D108: Res 2.87K Ohm 1, Yageo | E108: 4 | F108: Ready for unified AVL | G108: Review the suggested preferred PN and publish one controlled AVL entry.
A109: R_20.5kOhm_1%_0.0625W__0402 | B109: 10G212205214010 | C109: 4 | D109: Res 20.5K Ohm 1, Yageo | E109: 4 | F109: Ready for unified AVL | G109: Review the suggested preferred PN and publish one controlled AVL entry.
A110: R_200Ohm_1%_0.0625W__0402 | B110: 10G212200014010 | C110: 4 | D110: Res 200 Ohm 1, Yageo | E110: 12 | F110: Ready for unified AVL | G110: Review the suggested preferred PN and publish one controlled AVL entry.
A111: R_200kOhm_1%_0.0625W__0402 | B111: 10G212200314010 | C111: 4 | D111: Res 200K Ohm 1, Yageo | E111: 12 | F111: Ready for unified AVL | G111: Review the suggested preferred PN and publish one controlled AVL entry.
A112: R_20kOhm_1%_0.0625W__0402 | B112: 10102-00811100 | C112: 5 | D112: Res 20K Ohm 1, Yageo | E112: 45 | F112: Ready for unified AVL | G112: Review the suggested preferred PN and publish one controlled AVL entry.
A113: R_22.1kOhm_1%_0.0625W__0402 | B113: 10G212221214010 | C113: 4 | D113: Res 22.1K Ohm 1, Yageo | E113: 4 | F113: Ready for unified AVL | G113: Review the suggested preferred PN and publish one controlled AVL entry.
... A175: R_90.9kOhm_1%_0.0625W__0402 | B175: 10G212909214010 | C175: 4 | D175: Res 90.9K Ohm 1, Yageo | E175: 4 | F175: Ready for unified AVL | G175: Review the suggested preferred PN and publish one controlled AVL entry.

Sheet Risk Review
A1: Severity | B1: Risk | C1: PN | D1: Reference Count | E1: Finding | F1: Suggestion
A2: High | B2: Data quality | D2: 0 | E2: Missing manufacturer part number | F2: Complete the MPN before AVL, sourcing, or consolidation review.
A3: High | B3: Data quality | D3: 0 | E3: Missing manufacturer part number | F3: Complete the MPN before AVL, sourcing, or consolidation review.
A4: High | B4: Supply continuity | C4: 11203-0091F100 | D4: 2 | E4: Single-source specification risk | F4: Qualify an alternate source and maintain it in the AVL.
A5: High | B5: Supply continuity | C5: 11203-0060Q000 | D5: 4 | E5: Single-source specification risk | F5: Qualify an alternate source and maintain it in the AVL.
A6: High | B6: Supply continuity | C6: 11G232110415320 | D6: 4 | E6: Single-source specification risk | F6: Qualify an alternate source and maintain it in the AVL.
A7: High | B7: Supply continuity | C7: 11207-0065D000 | D7: 7 | E7: Single-source specification risk | F7: Qualify an alternate source and maintain it in the AVL.
A8: High | B8: Supply continuity | C8: 11204-0035F000 | D8: 0 | E8: Single-source specification risk | F8: Qualify an alternate source and maintain it in the AVL.
A9: High | B9: Supply continuity | C9: 11203-0215F000 | D9: 7 | E9: Single-source specification risk | F9: Qualify an alternate source and maintain it in the AVL.
A10: High | B10: Supply continuity | C10: 11203-0402F000 | D10: 4 | E10: Single-source specification risk | F10: Qualify an alternate source and maintain it in the AVL.
A11: High | B11: Supply continuity | C11: 11G232222214320 | D11: 1 | E11: Single-source specification risk | F11: Qualify an alternate source and maintain it in the AVL.
A12: High | B12: Supply continuity | C12: 11203-0154F000 | D12: 8 | E12: Single-source specification risk | F12: Qualify an alternate source and maintain it in the AVL.
A13: High | B13: Supply continuity | C13: 11202-0359Q000 | D13: 2 | E13: Single-source specification risk | F13: Qualify an alternate source and maintain it in the AVL.
A14: High | B14: Supply continuity | C14: 11203-0061F000 | D14: 2 | E14: Single-source specification risk | F14: Qualify an alternate source and maintain it in the AVL.
A15: High | B15: Supply continuity | C15: 11206-0005F000 | D15: 6 | E15: Single-source specification risk | F15: Qualify an alternate source and maintain it in the AVL.
... A21: High | B21: Supply continuity | C21: 10G212750214040 | D21: 3 | E21: Single-source specification risk | F21: Qualify an alternate source and maintain it in the AVL.

Sheet Settings
A1: Section | B1: Name | C1: Value | D1: Source
A2: Summary | B2: BOM Lines | C2: 909
A3: Summary | B3: Total Component Quantity | C3: 5780
A4: Summary | B4: MLCC Lines | C4: 322
A5: Summary | B5: MLCC Quantity | C5: 2707
A6: Summary | B6: MLCC Specifications | C6: 70
A7: Summary | B7: Duplicate PN Groups | C7: 158
A8: Summary | B8: Near Value Pairs | C8: 534
A9: Summary | B9: Near Resistance Pairs | C9: 502
A10: Summary | B10: Near Capacitance Pairs | C10: 32
A11: Summary | B11: Different Package Groups | C11: 9
A12: Summary | B12: Different Voltage Groups | C12: 12
A13: Summary | B13: Different Material Groups | C13: 9
... A22: Summary | B22: Overall Score | C22: 15
A23: Metadata | B23: Platform Version | C23: 2.0.0
A24: Metadata | B24: Generated UTC | C24: 2026-07-24T08:28:28+00:00
A25: Metadata | B25: Project Name | C25: P303NV
A26: Metadata | B26: Rule Source | C26: E:\GitHub\BOM_Normalization_Tool\config\default_rules.json; runtime near-value override
A27: Metadata | B27: Rule Schema Version | C27: 1
A28: Metadata | B28: Resistor Near-Value Ratio | C28: 2.2
A29: Metadata | B29: Capacitor Near-Value Ratio | C29: 2.2
A30: Metadata | B30: Analyzed Rows | C30: 909
A31: Metadata | B31: Input File | C31: E:\GitHub\BOM_Normalization_Tool\output\60bom.xlsx
A32: Metadata | B32: Input Type | C32: Excel workbook
A33: Metadata | B33: Selected Sheet | C33: My Excel Sheet
A34: Metadata | B34: Detected Header Row | C34: 1
A35: Rules | B35: schema_version | C35: 1 | D35: E:\GitHub\BOM_Normalization_Tool\config\default_rules.json; runtime near-value override
A36: Rules | B36: analysis.near_value_ratio.R | C36: 2.2 | D36: E:\GitHub\BOM_Normalization_Tool\config\default_rules.json; runtime near-value override
A37: Rules | B37: analysis.near_value_ratio.C | C37: 2.2 | D37: E:\GitHub\BOM_Normalization_Tool\config\default_rules.json; runtime near-value override
A38: Rules | B38: analysis.voltage_ratio_limit | C38: 4 | D38: E:\GitHub\BOM_Normalization_Tool\config\default_rules.json; runtime near-value override
A39: Rules | B39: analysis.minimum_complete_spec_fields | C39: 4 | D39: E:\GitHub\BOM_Normalization_Tool\config\default_rules.json; runtime near-value override
A40: Rules | B40: risk.lifecycle_keywords | C40: ["EOL", "OBSOLETE", "DISCONTINUED", "NRND", "NOT RECOMMENDED", "LAST TIME BUY"] | D40: E:\GitHub\BOM_Normalization_Tool\config\default_rules.json; runtime near-value override
A41: Rules | B41: risk.single_source_vendor_limit | C41: 1 | D41: E:\GitHub\BOM_Normalization_Tool\config\default_rules.json; runtime near-value override
A42: Rules | B42: risk.high_fragmentation_pn_count | C42: 3 | D42: E:\GitHub\BOM_Normalization_Tool\config\default_rules.json; runtime near-value override
A43: Rules | B43: risk.unknown_vendor_is_risk | C43: TRUE | D43: E:\GitHub\BOM_Normalization_Tool\config\default_rules.json; runtime near-value override
A44: Rules | B44: risk.missing_part_number_is_risk | C44: TRUE | D44: E:\GitHub\BOM_Normalization_Tool\config\default_rules.json; runtime near-value override
A45: Rules | B45: avl.minimum_vendors | C45: 2 | D45: E:\GitHub\BOM_Normalization_Tool\config\default_rules.json; runtime near-value override
A46: Rules | B46: avl.approved_vendors | C46: [] | D46: E:\GitHub\BOM_Normalization_Tool\config\default_rules.json; runtime near-value override
A47: Rules | B47: avl.blocked_vendors | C47: [] | D47: E:\GitHub\BOM_Normalization_Tool\config\default_rules.json; runtime near-value override
A48: Rules | B48: cost_down.minimum_impact_quantity | C48: 1 | D48: E:\GitHub\BOM_Normalization_Tool\config\default_rules.json; runtime near-value override
...
